Workbook

Sheet Index
A1: =Assumptions!A1 -> Bharti Airtel Ltd.
B3: 📥 INPUTS
B5: Assumptions
B6: P&L Input
B7: BS Input
B8: CF Input
B9: Market Data
B10: Equity Beta
B11: Comps Data
B14: 📊Calculation & Analysis
B16: Common Sizing
B17: Revenue Build-up
B18: Working Capital
... B27: FAS

Sheet Assumptions
A1: Bharti Airtel Ltd.
B7: Company Description | C7: Bharti Airtel Ltd.
B8: ISIN Code | C8: INE397D01024
B9: Sector Name | C9: Telecommunication
B10: Industry | C10: Telecom Services
B11: Exchange Name | C11: BSE:532454 NSE:BHARTIARTL
B12: Website | C12: https://www.airtel.in
B13: Company Description | C13: Bharti Airtel Limited is one of India's leading telecommunications companies and a global provider of communication and digital services. Founded in 1995 and headquartered in Gurugram, Haryana, the company operates across India and 14 countries in Africa. Airtel offers a diversified portfolio including mobile services, broadband, digital TV, enterprise solutions, data centers, cloud services, and fintech through Airtel Payments Bank. The company serves over 590 million customers globally and has established a strong market position through continuous investments in network infrastructure, spectrum assets, and digital technologies. Airtel's business model is supported by multiple revenue streams across consumer, enterprise, home broadband, and infrastructure services. For FY2025–26, Bharti Airtel reported consolidated revenue of ₹2,109.7 billion and net profit of ₹338.2 billion, reflecting strong operational performance driven by customer additions, higher data consumption, premiumization, and expansion of digital services.
B14: Current Market Price | C14: 1949
B17: Scenario | D17: Case
B18: Base case | D18: =IF(B18="Best case",1,IF(B18="Base case",2,3)) -> 2
B21: Company data
B22: Particulars | D22: Amount
B23: No of Outstanding shares | C23: Nos | D23: 6094393000
B24: Face Value per share | C24: Rs. | D24: 5
B25: Current Market Price | C25: Rs. | D25: =C14 -> 1949
B26: Market Capitalisation | C26: INR in Crs | D26: =D23*D25/10^7 -> 1187797.2
B29: Assumptions
B30: Perpetual Growth rate | C30: % | D30: 0.04
B31: 10 year Bond yield rate | C31: % | D31: 0.06707
B32: Interest rate | C32: % | D32: =AVERAGE('Income Statement'!C31/('Balance Sheet'!C50+'Balance Sheet'!C61+'Balance Sheet'!C51+'Balance Sheet'!C62),'Income Statement'!D31/('Balance Sheet'!D50+'Balance Sheet'!D61+'Balance Sheet'!D51+'Balance Sheet'!D62),'Income Statement'!E31/('Balance Sheet'!E50+'Balance Sheet'!E61+'Balance Sheet'!E51+'Balance Sheet'!E62),'Income Statement'!F31/('Balance Sheet'!F50+'Balance Sheet'!F61+'Balance Sheet'!F51+'Balance Sheet'!F62),'Income Statement'!G31/('Balance Sheet'!G50+'Balance Sheet'!G61+'Balance Sheet'!G51+'Balance Sheet'!G62))*(1-'Cost Builup'!G34) -> 0.074948986
H34: (INR in millions)
B35: Company Revenue by Geography
B36: Year | C36: India | E36: Africa | G36: South Asia | I36: Others
B37: 2022 | C37: 777402 | E37: 345611 | G37: 3716 | I37: 38740
B38: =B37+1 -> 2023 | C38: 928568 | E38: 416024 | G38: 2669 | I38: 44187
B39: =B38+1 -> 2024 | C39: 1041523 | E39: 404995 | G39: 3469 | I39: 49837
B40: =B39+1 -> 2025 | C40: 1264125 | E40: 413798 | G40: 878 | I40: 51051
B41: =B40+1 -> 2026 | C41: 1550658 | E41: 520330 | G41: 8719 | I41: 30021
B46: Headings | C46: Reference | D46: Assumptions
B47: Revenue Buildup | C47: H29:Q29 | D47: Revenue Forecasting Assumptions • Mobile Services India: Forecast based on the 5-year historical average growth with gradual annual tapering. • Mobile Services Africa: Forecast based on historical average growth with gradual tapering. • Airtel Business: Forecast based on historical average growth and gradual moderation. • Passive Infrastructure Services: Forecast based on historical average growth with gradual tapering. • Homes Services: Forecast based on historical average growth and gradual tapering. • Other Operating Revenue: Forecast based on historical average/median growth. • Exceptional Items: Forecast based on historical average progression. No abnormal future gains assumed. • Discontinued revenue segments have not been projected beyond the historical period.
C48: H18:Q18 G12:Q12 | D48: Other Income and Exceptional Items for the forecast period 2027–2036 are projected as a constant percentage of total revenue, calculated based on the 5-year average audited for Other Income and the 3-year average audited for Exceptional Items.
B49: Cost Buildup | C49: H22:Q22 H28:Q28 | D49: Employee Benefit Expenses and Other Expenses for the forecast period 2027–2036 are projected as a constant percentage of total revenue, based on the 5-year audited average.
C50: H31:Q31 | D50: Finance Costs are estimated using a fixed borrowing rate, derived from the five-year average of interest expenses relative to total debt, and applied consistently throughout the projected period.
C51: H34:Q34 | D51: Tax rate is derived from the latest audited figures, starting at 25% in FY2026 after a 0.5% uplift. It is expected to rise by 1% every two years over the forecast period.
B52: FAS | C52: H173:Q173 | D52: Since FY2026 audited financial data is not available, FY2025 figures have been used as the base for forecasting the additions, disposals and depreciation of Property, Plant & Equipment (PPE), Intangible Assets and ROU Assets. A conservative growth rate of 4% has been assumed for the first projected year and every 3 years thereafter.
C53: H173:Q173 | D53: Capital WIP is forecasted at same absolute growth and increased by 4% for every 3 years.
B54: BS Items | C54: H12:Q12 H61:Q61 | D54: Balance sheet items are projected as % on Revenue using the latest previous year's % as base otherwise as mentioned and Borrowings are adjusted (assumed to be taken/repaid) based on availability of Cash & Cash equivalents
B55: Working Capital | C55: H11:Q11 H12:Q12 | D55: Trade Receivables and Trade Payables are projected as a fixed percentage of revenue, based on the average proportions observed over the last five audited years.
B56: Income Statement | C56: H48:Q48 | D56: Total dividend payments have been projected by assuming a constant dividend payout ratio of 21%, based on the latest historical payout trend. The payout ratio has been maintained throughout the forecast period (FY2027–FY2036).
...

Sheet P&L Input
A1: Bharti Airtel Ltd
F6: (INR in millions)
B7: P&L Input
B8: Particulars | C8: 2022 | D8: =C8+1 -> 2023 | E8: =D8+1 -> 2024 | F8: =E8+1 -> 2025 | G8: =F8+1 -> 2026
C9: Audited | D9: Audited | E9: Audited | F9: Audited | G9: Audited
B11: Revenue from Sale of Service | C11: 1165469 | D11: 1391448 | E11: 1499824 | F11: 1729852 | G11: 2109728
B12: Other Operating Revenue | C12: 5343 | D12: 9366 | E12: 14354 | F12: 15737 | G12: 28173
B14: Total Income | C14: =SUM(C11:C12) -> 1170812 | D14: =SUM(D11:D12) -> 1400814 | E14: =SUM(E11:E12) -> 1514178 | F14: =SUM(F11:F12) -> 1745589 | G14: =SUM(G11:G12) -> 2137901
B16: Expenses
B17: Network operating expenses | C17: 250205 | D17: 285433 | E17: 300188 | F17: 335043 | G17: 397500
B18: Access charges | C18: 67611 | D18: 76207 | E18: 75185 | F18: 71713 | G18: 55416
B19: License fee / Spectrum charges | C19: 110636 | D19: 117517 | E19: 120358 | F19: 138290 | G19: 153729
B20: Employee benefits expense | C20: 44333 | D20: 48308 | E20: 53231 | F20: 63089 | G20: 75813
B21: Sales and marketing expenses | C21: 53035 | D21: 72454 | E21: 107882 | F21: 114601 | G21: 131073
B22: Other expenses | C22: 64310 | D22: 78794 | E22: 60062 | F22: 75524 | G22: 99452
B24: Total Expenses | C24: =SUM(C17:C23) -> 590130 | D24: =SUM(D17:D23) -> 678713 | E24: =SUM(E17:E23) -> 716906 | F24: =SUM(F17:F23) -> 798260 | G24: =SUM(G17:G23) -> 912983
B26: EBITDA | C26: =C14-C24 -> 580682 | D26: =D14-D24 -> 722101 | E26: =E14-E24 -> 797272 | F26: =F14-F24 -> 947329 | G26: =G14-G24 -> 1224918
B28: Depreciation & Amortisation | C28: 330907 | D28: 364318 | E28: 395376 | F28: 455703 | G28: 527108
B30: EBIT | C30: =C26-C28 -> 249775 | D30: =D26-D28 -> 357783 | E30: =E26-E28 -> 401896 | F30: =F26-F28 -> 491626 | G30: =G26-G28 -> 697810
B32: Finance Costs | C32: 166162 | D32: 192999 | E32: 226477 | F32: 217539 | G32: 215553
B33: Share of Profit/(Loss) of Associates | C33: -24232 | D33: -7521 | E33: -27094 | F33: -37030 | G33: -3645
B35: Profit before exceptional items | C35: =C30-C32-C33 -> 107845 | D35: =D30-D32-D33 -> 172305 | E35: =E30-E32-E33 -> 202513 | F35: =F30-F32-F33 -> 311117 | G35: =G30-G32-G33 -> 485902
B37: Exceptional items | C37: -16986 | D37: 6698 | E37: 75723 | F37: -72868 | G37: 34175
B39: Profit before Tax | C39: =C35-C37 -> 124831 | D39: =D35-D37 -> 165607 | E39: =E35-E37 -> 126790 | F39: =F35-F37 -> 383985 | G39: =G35-G37 -> 451727
B41: Taxes | C41: 41779 | D41: 42733 | E41: 41210 | F41: 9172 | G41: 113499
B43: Net Profit | C43: =C39-C41 -> 83052 | D43: =D39-D41 -> 122874 | E43: =E39-E41 -> 85580 | F43: =F39-F41 -> 374813 | G43: =G39-G41 -> 338228
B46: KPIs
B47: Revenue % (y-o-y) | C47: - | D47: =D11/C11-1 -> 0.19389533 | E47: =E11/D11-1 -> 0.077887208 | F47: =F11/E11-1 -> 0.15337 | G47: =G11/F11-1 -> 0.21960029
B48: EBITDA% | C48: =C26/C14 -> 0.49596519 | D48: =D26/D14 -> 0.51548671 | E48: =E26/E14 -> 0.52653783 | F48: =F26/F14 -> 0.54269877 | G48: =G26/G14 -> 0.57295357
B49: EBIT % | C49: =C30/C14 -> 0.21333485 | D49: =D30/D14 -> 0.25541078 | E49: =E30/E14 -> 0.2654219 | F49: =F30/F14 -> 0.28163903 | G49: =G30/G14 -> 0.32639959
B50: NP % | C50: =C43/C14 -> 0.070935385 | D50: =D43/D14 -> 0.087716142 | E50: =E43/E14 -> 0.056519115 | F50: =F43/F14 -> 0.21472007 | G50: =G43/G14 -> 0.15820564
B51: ROA | C51: =C43/'BS Input'!C38 -> 0.022838067 | D51: =D43/'BS Input'!D38 -> 0.027511166 | E51: =E43/'BS Input'!E38 -> 0.019251751 | F51: =F43/'BS Input'!F38 -> 0.072869723 | G51: =G43/'BS Input'!G38 -> 0.061256365
B52: Asset Turnover | C52: =C11/'BS Input'!C38 -> 0.32048667 | D52: =D11/'BS Input'!D38 -> 0.31154155 | E52: =E11/'BS Input'!E38 -> 0.33739469 | F52: =F11/'BS Input'!F38 -> 0.33631127 | G52: =G11/'BS Input'!G38 -> 0.38209216
B53: Assets / Equity | C53: ='BS Input'!C38/'BS Input'!C45 -> 3.9555773 | D53: ='BS Input'!D38/'BS Input'!D45 -> 4.1959335 | E53: ='BS Input'!E38/'BS Input'!E45 -> 4.2110134 | F53: ='BS Input'!F38/'BS Input'!F45 -> 3.3515873 | G53: ='BS Input'!G38/'BS Input'!G45 -> 2.8176261
B54: ROE | C54: =C50*C52*C53 -> 0.089925482 | D54: =D50*D52*D53 -> 0.11466321 | E54: =E50*E52*E53 -> 0.080300865 | F54: =F50*F52*F53 -> 0.24202744 | G54: =G50*G52*G53 -> 0.17032307

Sheet BS Input
A1: Bharti Airtel Ltd
B5: Blue- Hard Coded, Black- Calculation & Green- Linkages
G6: (INR in millions)
B7: Particulars | C7: 2022 | D7: 2023 | E7: 2024 | F7: 2025 | G7: 2026
B8: ASSETS
B9: Non-current assets
B10: Property, Plant & Equipment | C10: 905725 | D10: 952241 | E10: 1066121 | F10: 1432724 | G10: 1570659
B11: Capital Work-in-Progress | C11: 42386 | D11: 110293 | E11: 89077 | F11: 105962 | G11: 126131
B12: Right-of-use Assets | C12: 322286 | D12: 546466 | E12: 559367 | F12: 602415 | G12: 673244
B13: Goodwill | C13: 338313 | D13: 337741 | E13: 265017 | F13: 516974 | G13: 566859
B14: Other Intangible Assets | C14: 874509 | D14: 937490 | E14: 1142526 | F14: 1332569 | G14: 1252604
B15: Intangible Assets Under Development | C15: 17161 | D15: 383961 | E15: 79964 | F15: 4027 | G15: 3250
B16: Investment in Joint Ventures & Associates | C16: 284268 | D16: 281838 | E16: 312404 | F16: 36416 | G16: 40622
B17: Financial Assets
B18: Investments | C18: 609 | D18: 656 | E18: 924 | F18: 5435 | G18: 11385
B19: Derivative instruments | C19: 218 | D19: 854 | E19: 65 | F19: - | G19: -
B20: Trade Receivables | E20: 1805 | F20: 2131 | G20: 2544
B21: Loans | C21: – | D21: – | E21: - | F21: 865 | G21: –
B22: Other Financial Assets | C22: 22515 | D22: 25963 | E22: 26557 | F22: 37471 | G22: 35700
B23: Income Tax Assets (Net) | C23: 17479 | D23: 20399 | E23: 14135 | F23: 24978 | G23: 20181
B24: Deferred Tax Assets (Net) | C24: 199250 | D24: 189519 | E24: 192428 | F24: 249111 | G24: 191413
B25: Other Non-current Assets | C25: 91562 | D25: 103898 | E25: 112159 | F25: 116638 | G25: 124770
B26: Total Non-current Assets | C26: =SUM(C10:C25) -> 3116281 | D26: =SUM(D10:D25) -> 3891319 | E26: =SUM(E10:E25) -> 3862549 | F26: =SUM(F10:F25) -> 4467716 | G26: =SUM(G10:G25) -> 4619362
B27: Current Assets
B28: Inventories | C28: 3750 | D28: 2576 | E28: 3639 | F28: 4517 | G28: 6009
B29: Investments | C29: 8614 | D29: 47045 | E29: 2695 | F29: 16532 | G29: 137006
B30: Derivative Instruments | C30: 561 | D30: 1283 | E30: 1168 | F30: 813 | G30: 5040
B31: Trade Receivables | C31: 40562 | D31: 39815 | E31: 47277 | F31: 74557 | G31: 79776
B32: Cash & Cash Equivalents | C32: 60959 | D32: 71794 | E32: 69155 | F32: 61056 | G32: 137222
B33: Other Bank Balances | C33: 73984 | D33: 62392 | E33: 94244 | F33: 106143 | G33: 166546
B34: Other Financial Assets | C34: 214697 | D34: 220865 | E34: 249544 | F34: 267662 | G34: 244264
B35: Other Current Assets | C35: 117152 | D35: 129243 | E35: 115039 | F35: 144608 | G35: 125718
B36: Assets Held for Sale | C36: – | D36: – | E36: – | F36: – | G36: 573
B37: Total Current Assets | C37: =SUM(C28:C36) -> 520279 | D37: =SUM(D28:D36) -> 575013 | E37: =SUM(E28:E36) -> 582761 | F37: =SUM(F28:F36) -> 675888 | G37: =SUM(G28:G36) -> 902154
B38: TOTAL ASSETS | C38: =C26+C37 -> 3636560 | D38: =D26+D37 -> 4466332 | E38: =E26+E37 -> 4445310 | F38: =F26+F37 -> 5143604 | G38: =G26+G37 -> 5521516
B40: EQUITY & LIABILITIES
B41: Share Capital | C41: 27950 | D41: 28366 | E41: 28766 | F41: 29001 | G41: 30468
B42: Other Equity | C42: 637593 | D42: 747263 | E42: 791422 | F42: 1107718 | G42: 1460098
B43: Equity attributable to Owners | C43: =SUM(C41:C42) -> 665543 | D43: =SUM(D41:D42) -> 775629 | E43: =SUM(E41:E42) -> 820188 | F43: =SUM(F41:F42) -> 1136719 | G43: =SUM(G41:G42) -> 1490566
B44: Non-controlling Interests | C44: 253807 | D44: 288814 | E44: 235451 | F44: 397958 | G44: 469068
...

Sheet CF Input
A1: Bharti Airtel Ltd
B7: Cash Flows from Operating Activities
G8: (INR in millions)
B9: Particulars | C9: FY2022 | D9: FY2023 | E9: FY2024 | F9: FY2025 | G9: FY2026
B10: Profit before tax | C10: 124831 | D10: 165607 | E10: 126790 | F10: 383985 | G10: 451727
B11: Adjustments for:
B12: Depreciation and amortisation expenses | C12: 330907 | D12: 364318 | E12: 395376 | F12: 455703 | G12: 527108
B13: Finance costs | C13: 165241 | D13: 188434 | E13: 219337 | F13: 216258 | G13: 214485
B14: Net gain on FVTPL instruments | C14: -1067 | D14: -2474 | E14: -2645 | F14: -2048 | G14: -3369
B15: Dividend income | C15: - | D15: - | E15: - | F15: - | G15: -272
B16: Interest income | C16: -2206 | D16: -3080 | E16: -6493 | F16: -5306 | G16: -11158
B17: Net (gain)/loss on derivative financial instruments | C17: 947 | D17: 3013 | E17: 6319 | F17: 420 | G17: -2017
B18: Share of profit of associates and JVs (net) | C18: -24232 | D18: -7521 | E18: -27094 | F18: -37030 | G18: -3645
B19: Exceptional items (net) | C19: -11705 | D19: 6698 | E19: 75723 | F19: -72868 | G19: 34175
B20: Employee share based payment expense | C20: 776 | D20: 1115 | E20: 1194 | F20: 1669 | G20: 3157
B21: (Profit)/Loss on sale of PP&E | C21: 74 | D21: 22 | E21: 44 | F21: -1031 | G21: -2985
B22: Provision for doubtful debts / bad debts written off | C22: 3048 | D22: 5664 | E22: 4278 | F22: 3741 | G22: 3586
B23: Other non-cash items | C23: -222 | D23: 485 | E23: 823 | F23: 396 | G23: 2301
B24: Operating cash flows before changes in assets/liabilities | C24: =SUM(C10:C23) -> 586392 | D24: =SUM(D10:D23) -> 722281 | E24: =SUM(E10:E23) -> 793652 | F24: =SUM(F10:F23) -> 943889 | G24: =SUM(G10:G23) -> 1213093
B25: Changes in assets and liabilities
B26: Trade receivables | C26: -7131 | D26: -5583 | E26: -14941 | F26: 29658 | G26: -5654
B27: Trade payables | C27: -4877 | D27: 12671 | E27: 6398 | F27: 8586 | G27: 24977
B28: Inventories | C28: -1181 | D28: -1157 | E28: -771 | F28: -1416 | G28: -1982
B29: Provisions | C29: 2736 | D29: 6494 | E29: 17332 | F29: 22699 | G29: 18276
B30: Other financial and non-financial liabilities | C30: 11655 | D30: -11991 | E30: 41516 | F30: 48154 | G30: 33760
B31: Other financial and non-financial assets | C31: -15674 | D31: -31554 | E31: -25398 | F31: -23868 | G31: 2665
B32: Net cash generated from operations before tax | C32: 571920 | D32: 691161 | E32: 817788 | F32: 1027702 | G32: 1285135
B33: Income tax paid (net) | C33: -21754 | D33: -37915 | E33: -28806 | F33: -44380 | G33: -62839
B34: Net cash generated from operating activities (a) | C34: =C32+C33 -> 550166 | D34: =D32+D33 -> 653246 | E34: =E32+E33 -> 788982 | F34: =F32+F33 -> 983322 | G34: =G32+G33 -> 1222296
B36: Cash Flows from Investing Activities
B37: Purchase of PP&E and capital WIP | C37: -265406 | D37: -260566 | E37: -381915 | F37: -379077 | G37: -451756
B38: Proceeds from sale of PP&E | C38: 13791 | D38: 885 | E38: 1228 | F38: 3382 | G38: 11680
B39: Purchase of intangible assets | C39: -8593 | D39: -4819 | E39: -18600 | F39: -17722 | G39: -15386
B40: Payment towards spectrum* | C40: -174482 | D40: -123684 | E40: -121547 | F40: -213487 | G40: -8546
B41: Proceeds from sale of spectrum | C41: 10048 | D41: - | E41: - | F41: - | G41: -
B42: Proceeds from sale of business | C42: 998 | D42: - | E42: - | F42: - | G42: -
B43: (Purchase)/proceeds sale of current investments (net) | C43: 21298 | D43: -12000 | E43: 19015 | F43: 7100 | G43: -126994
B44: Proceeds from sale of non-current investments | C44: - | D44: 311 | E44: 69 | F44: 300 | G44: 90
B45: Purchase of non-current investments | C45: -89 | D45: -323 | E45: -304 | F45: -734 | G45: -1241
B46: Proceeds from sale of tower subsidiary (net) | C46: 5887 | D46: - | E46: - | F46: - | G46: -
...

Sheet Common Sizing
A1: Bharti Airtel Ltd
G6: (INR in millions)
B7: Common Sizing
B8: Particulars | C8: 2022 | D8: =C8+1 -> 2023 | E8: =D8+1 -> 2024 | F8: =E8+1 -> 2025 | G8: =F8+1 -> 2026
C9: Audited | D9: Audited | E9: Audited | F9: Audited | G9: Audited
B11: Revenue from Sale of Service | C11: ='P&L Input'!C11/'P&L Input'!C$14 -> 0.9954365 | D11: ='P&L Input'!D11/'P&L Input'!D$14 -> 0.99331389 | E11: ='P&L Input'!E11/'P&L Input'!E$14 -> 0.99052027 | F11: ='P&L Input'!F11/'P&L Input'!F$14 -> 0.9909847 | G11: ='P&L Input'!G11/'P&L Input'!G$14 -> 0.98682212
B12: Other Operating Revenue | C12: ='P&L Input'!C12/'P&L Input'!C$14 -> 0.0045634995 | D12: ='P&L Input'!D12/'P&L Input'!D$14 -> 0.0066861125 | E12: ='P&L Input'!E12/'P&L Input'!E$14 -> 0.0094797309 | F12: ='P&L Input'!F12/'P&L Input'!F$14 -> 0.0090152951 | G12: ='P&L Input'!G12/'P&L Input'!G$14 -> 0.013177879
B14: Total Income | C14: ='P&L Input'!C14/'P&L Input'!C$14 -> 1 | D14: ='P&L Input'!D14/'P&L Input'!D$14 -> 1 | E14: ='P&L Input'!E14/'P&L Input'!E$14 -> 1 | F14: ='P&L Input'!F14/'P&L Input'!F$14 -> 1 | G14: ='P&L Input'!G14/'P&L Input'!G$14 -> 1
B16: Expenses | C16: ='P&L Input'!C16/'P&L Input'!C$14 -> 0 | D16: ='P&L Input'!D16/'P&L Input'!D$14 -> 0 | E16: ='P&L Input'!E16/'P&L Input'!E$14 -> 0 | F16: ='P&L Input'!F16/'P&L Input'!F$14 -> 0 | G16: ='P&L Input'!G16/'P&L Input'!G$14 -> 0
B17: Network operating expenses | C17: ='P&L Input'!C17/'P&L Input'!C$14 -> 0.21370211 | D17: ='P&L Input'!D17/'P&L Input'!D$14 -> 0.20376224 | E17: ='P&L Input'!E17/'P&L Input'!E$14 -> 0.19825146 | F17: ='P&L Input'!F17/'P&L Input'!F$14 -> 0.19193693 | G17: ='P&L Input'!G17/'P&L Input'!G$14 -> 0.18593003
B18: Access charges | C18: ='P&L Input'!C18/'P&L Input'!C$14 -> 0.057747102 | D18: ='P&L Input'!D18/'P&L Input'!D$14 -> 0.054401941 | E18: ='P&L Input'!E18/'P&L Input'!E$14 -> 0.049654004 | F18: ='P&L Input'!F18/'P&L Input'!F$14 -> 0.041082408 | G18: ='P&L Input'!G18/'P&L Input'!G$14 -> 0.025920751
B19: License fee / Spectrum charges | C19: ='P&L Input'!C19/'P&L Input'!C$14 -> 0.094495103 | D19: ='P&L Input'!D19/'P&L Input'!D$14 -> 0.083891937 | E19: ='P&L Input'!E19/'P&L Input'!E$14 -> 0.079487352 | F19: ='P&L Input'!F19/'P&L Input'!F$14 -> 0.079222543 | G19: ='P&L Input'!G19/'P&L Input'!G$14 -> 0.07190651
B20: Employee benefits expense | C20: ='P&L Input'!C20/'P&L Input'!C$14 -> 0.037865174 | D20: ='P&L Input'!D20/'P&L Input'!D$14 -> 0.034485663 | E20: ='P&L Input'!E20/'P&L Input'!E$14 -> 0.035155048 | F20: ='P&L Input'!F20/'P&L Input'!F$14 -> 0.036141956 | G20: ='P&L Input'!G20/'P&L Input'!G$14 -> 0.035461418
B21: Sales and marketing expenses | C21: ='P&L Input'!C21/'P&L Input'!C$14 -> 0.045297623 | D21: ='P&L Input'!D21/'P&L Input'!D$14 -> 0.051722784 | E21: ='P&L Input'!E21/'P&L Input'!E$14 -> 0.071247898 | F21: ='P&L Input'!F21/'P&L Input'!F$14 -> 0.065651766 | G21: ='P&L Input'!G21/'P&L Input'!G$14 -> 0.0613092
B22: Other expenses | C22: ='P&L Input'!C22/'P&L Input'!C$14 -> 0.054927691 | D22: ='P&L Input'!D22/'P&L Input'!D$14 -> 0.056248724 | E22: ='P&L Input'!E22/'P&L Input'!E$14 -> 0.039666406 | F22: ='P&L Input'!F22/'P&L Input'!F$14 -> 0.043265626 | G22: ='P&L Input'!G22/'P&L Input'!G$14 -> 0.046518524
B24: Total Expenses | C24: ='P&L Input'!C24/'P&L Input'!C$14 -> 0.50403481 | D24: ='P&L Input'!D24/'P&L Input'!D$14 -> 0.48451329 | E24: ='P&L Input'!E24/'P&L Input'!E$14 -> 0.47346217 | F24: ='P&L Input'!F24/'P&L Input'!F$14 -> 0.45730123 | G24: ='P&L Input'!G24/'P&L Input'!G$14 -> 0.42704643
B26: EBITDA | C26: ='P&L Input'!C26/'P&L Input'!C$14 -> 0.49596519 | D26: ='P&L Input'!D26/'P&L Input'!D$14 -> 0.51548671 | E26: ='P&L Input'!E26/'P&L Input'!E$14 -> 0.52653783 | F26: ='P&L Input'!F26/'P&L Input'!F$14 -> 0.54269877 | G26: ='P&L Input'!G26/'P&L Input'!G$14 -> 0.57295357
... B43: Net Profit | C43: ='P&L Input'!C43/'P&L Input'!C$14 -> 0.070935385 | D43: ='P&L Input'!D43/'P&L Input'!D$14 -> 0.087716142 | E43: ='P&L Input'!E43/'P&L Input'!E$14 -> 0.056519115 | F43: ='P&L Input'!F43/'P&L Input'!F$14 -> 0.21472007 | G43: ='P&L Input'!G43/'P&L Input'!G$14 -> 0.15820564
B46: ASSETS
B47: Non-current assets
B48: Property, Plant & Equipment | C48: ='BS Input'!C10/'BS Input'!C$38 -> 0.24906093 | D48: ='BS Input'!D10/'BS Input'!D$38 -> 0.21320426 | E48: ='BS Input'!E10/'BS Input'!E$38 -> 0.23983052 | F48: ='BS Input'!F10/'BS Input'!F$38 -> 0.27854477 | G48: ='BS Input'!G10/'BS Input'!G$38 -> 0.28446155
B49: Capital Work-in-Progress | C49: ='BS Input'!C11/'BS Input'!C$38 -> 0.011655521 | D49: ='BS Input'!D11/'BS Input'!D$38 -> 0.024694313 | E49: ='BS Input'!E11/'BS Input'!E$38 -> 0.020038423 | F49: ='BS Input'!F11/'BS Input'!F$38 -> 0.020600731 | G49: ='BS Input'!G11/'BS Input'!G$38 -> 0.022843545
B50: Right-of-use Assets | C50: ='BS Input'!C12/'BS Input'!C$38 -> 0.088623864 | D50: ='BS Input'!D12/'BS Input'!D$38 -> 0.1223523 | E50: ='BS Input'!E12/'BS Input'!E$38 -> 0.12583307 | F50: ='BS Input'!F12/'BS Input'!F$38 -> 0.11711924 | G50: ='BS Input'!G12/'BS Input'!G$38 -> 0.12193101
B51: Goodwill | C51: ='BS Input'!C13/'BS Input'!C$38 -> 0.093031051 | D51: ='BS Input'!D13/'BS Input'!D$38 -> 0.075619323 | E51: ='BS Input'!E13/'BS Input'!E$38 -> 0.059617215 | F51: ='BS Input'!F13/'BS Input'!F$38 -> 0.10050813 | G51: ='BS Input'!G13/'BS Input'!G$38 -> 0.10266365
B52: Other Intangible Assets | C52: ='BS Input'!C14/'BS Input'!C$38 -> 0.24047699 | D52: ='BS Input'!D14/'BS Input'!D$38 -> 0.20990155 | E52: ='BS Input'!E14/'BS Input'!E$38 -> 0.2570183 | F52: ='BS Input'!F14/'BS Input'!F$38 -> 0.25907302 | G52: ='BS Input'!G14/'BS Input'!G$38 -> 0.22685871
B53: Intangible Assets Under Development | C53: ='BS Input'!C15/'BS Input'!C$38 -> 0.0047190202 | D53: ='BS Input'!D15/'BS Input'!D$38 -> 0.085967859 | E53: ='BS Input'!E15/'BS Input'!E$38 -> 0.017988397 | F53: ='BS Input'!F15/'BS Input'!F$38 -> 0.00078291408 | G53: ='BS Input'!G15/'BS Input'!G$38 -> 0.00058860646
B54: Investment in Joint Ventures & Associates | C54: ='BS Input'!C16/'BS Input'!C$38 -> 0.078169479 | D54: ='BS Input'!D16/'BS Input'!D$38 -> 0.063102788 | E54: ='BS Input'!E16/'BS Input'!E$38 -> 0.070277214 | F54: ='BS Input'!F16/'BS Input'!F$38 -> 0.0070798607 | G54: ='BS Input'!G16/'BS Input'!G$38 -> 0.0073570375
B55: Financial Assets
B56: Investments | C56: ='BS Input'!C18/'BS Input'!C$38 -> 0.00016746596 | D56: ='BS Input'!D18/'BS Input'!D$38 -> 0.00014687668 | E56: ='BS Input'!E18/'BS Input'!E$38 -> 0.00020785952 | F56: ='BS Input'!F18/'BS Input'!F$38 -> 0.0010566521 | G56: ='BS Input'!G18/'BS Input'!G$38 -> 0.0020619337
B57: Derivative instruments | C57: ='BS Input'!C19/'BS Input'!C$38 -> 5.9946763e-05 | D57: ='BS Input'!D19/'BS Input'!D$38 -> 0.00019120836 | E57: ='BS Input'!E19/'BS Input'!E$38 -> 1.4622152e-05 | F57: - | G57: -
B58: Trade Receivables | C58: ='BS Input'!C20/'BS Input'!C$38 -> 0 | D58: ='BS Input'!D20/'BS Input'!D$38 -> 0 | E58: ='BS Input'!E20/'BS Input'!E$38 -> 0.00040604592 | F58: ='BS Input'!F20/'BS Input'!F$38 -> 0.00041430095 | G58: ='BS Input'!G20/'BS Input'!G$38 -> 0.00046074303
B59: Loans | F59: ='BS Input'!F21/'BS Input'!F$38 -> 0.00016817002 | G59: -
B60: Other Financial Assets | C60: ='BS Input'!C22/'BS Input'!C$38 -> 0.0061912907 | D60: ='BS Input'!D22/'BS Input'!D$38 -> 0.0058130475 | E60: ='BS Input'!E22/'BS Input'!E$38 -> 0.0059741615 | F60: ='BS Input'!F22/'BS Input'!F$38 -> 0.0072849698 | G60: ='BS Input'!G22/'BS Input'!G$38 -> 0.0064656156
B61: Income Tax Assets (Net) | C61: ='BS Input'!C23/'BS Input'!C$38 -> 0.0048064655 | D61: ='BS Input'!D23/'BS Input'!D$38 -> 0.0045672825 | E61: ='BS Input'!E23/'BS Input'!E$38 -> 0.0031797557 | F61: ='BS Input'!F23/'BS Input'!F$38 -> 0.0048561281 | G61: ='BS Input'!G23/'BS Input'!G$38 -> 0.0036549745
B62: Deferred Tax Assets (Net) | C62: ='BS Input'!C24/'BS Input'!C$38 -> 0.054790791 | D62: ='BS Input'!D24/'BS Input'!D$38 -> 0.042432806 | E62: ='BS Input'!E24/'BS Input'!E$38 -> 0.04328787 | F62: ='BS Input'!F24/'BS Input'!F$38 -> 0.048431217 | G62: ='BS Input'!G24/'BS Input'!G$38 -> 0.034666747
B63: Other Non-current Assets | C63: ='BS Input'!C25/'BS Input'!C$38 -> 0.02517819 | D63: ='BS Input'!D25/'BS Input'!D$38 -> 0.023262489 | E63: ='BS Input'!E25/'BS Input'!E$38 -> 0.025230861 | F63: ='BS Input'!F25/'BS Input'!F$38 -> 0.022676318 | G63: ='BS Input'!G25/'BS Input'!G$38 -> 0.022597055
B64: Total Non-current Assets | C64: ='BS Input'!C26/'BS Input'!C$38 -> 0.856931 | D64: ='BS Input'!D26/'BS Input'!D$38 -> 0.8712561 | E64: ='BS Input'!E26/'BS Input'!E$38 -> 0.86890431 | F64: ='BS Input'!F26/'BS Input'!F$38 -> 0.86859642 | G64: ='BS Input'!G26/'BS Input'!G$38 -> 0.83661118
B65: Current Assets | C65: ='BS Input'!C27/'BS Input'!C$38 -> 0 | D65: ='BS Input'!D27/'BS Input'!D$38 -> 0 | E65: ='BS Input'!E27/'BS Input'!E$38 -> 0 | F65: ='BS Input'!F27/'BS Input'!F$38 -> 0 | G65: ='BS Input'!G27/'BS Input'!G$38 -> 0
B66: Inventories | C66: ='BS Input'!C28/'BS Input'!C$38 -> 0.0010311943 | D66: ='BS Input'!D28/'BS Input'!D$38 -> 0.00057675963 | E66: ='BS Input'!E28/'BS Input'!E$38 -> 0.00081861557 | F66: ='BS Input'!F28/'BS Input'!F$38 -> 0.00087817802 | G66: ='BS Input'!G28/'BS Input'!G$38 -> 0.0010882881
B67: Investments | C67: ='BS Input'!C29/'BS Input'!C$38 -> 0.0023687221 | D67: ='BS Input'!D29/'BS Input'!D$38 -> 0.010533252 | E67: ='BS Input'!E29/'BS Input'!E$38 -> 0.00060625693 | F67: ='BS Input'!F29/'BS Input'!F$38 -> 0.0032140888 | G67: ='BS Input'!G29/'BS Input'!G$38 -> 0.024813113
...

Sheet Revenue Buildup
A1: Bharti Airtel Ltd
P5: (INR in millions)
B6: Revenue Buildup
B7: Particulars | C7: =FAS!C7 -> 2022 | D7: =FAS!D7 -> 2023 | E7: =FAS!E7 -> 2024 | F7: =FAS!F7 -> 2025 | G7: =FAS!G7 -> 2026 | H7: =FAS!H7 -> 2027 | I7: =FAS!I7 -> 2028 | J7: =FAS!J7 -> 2029 | ... Q7: =FAS!Q7 -> 2036
C8: Audited | D8: Audited | E8: Audited | F8: Audited | G8: Audited | H8: Estimated | I8: Projected | J8: Projected | K8: Projected | L8: Projected | M8: Projected | N8: Projected | O8: Projected | P8: Projected | Q8: Projected
B10: Sale of Service | C10: =C76 -> 1165469 | D10: =D76 -> 1391448 | E10: =E76 -> 1499824 | F10: =F76 -> 1729852 | G10: =G76 -> 2109728 | H10: =H76 -> 2507801.6 | I10: =I76 -> 2823455.7 | J10: =J76 -> 3149592.4 | ... Q10: =Q76 -> 5195687.7
B11: Other Operating Revenues | C11: 5343 | D11: 9366 | E11: 14354 | F11: 15737 | G11: 28173 | H11: =H12*H10 -> 33488.816 | I11: =I12*I10 -> 37704.016 | J11: =J12*J10 -> 42059.198 | K11: =K12*K10 -> 46482.213 | L11: =L12*L10 -> 50890.149 | M11: =M12*M10 -> 55191.54 | N11: =N12*N10 -> 59289.291 | O11: =O12*O10 -> 63084.215 | ... Q11: =Q12*Q10 -> 69382.456
B12: (% on total Revenue) | C12: =C11/C10 -> 0.0045844205 | D12: =D11/D10 -> 0.0067311175 | E12: =E11/E10 -> 0.0095704563 | F12: =F11/F10 -> 0.0090973101 | G12: =G11/G10 -> 0.013353854 | H12: =G12 -> 0.013353854 | I12: =H12 -> 0.013353854 | J12: =I12 -> 0.013353854 | K12: =J12 -> 0.013353854 | L12: =K12 -> 0.013353854 | M12: =L12 -> 0.013353854 | N12: =M12 -> 0.013353854 | O12: =N12 -> 0.013353854 | ... Q12: =P12 -> 0.013353854
B14: Revenue from Operations | C14: =C10+C11 -> 1170812 | D14: =D10+D11 -> 1400814 | E14: =E10+E11 -> 1514178 | F14: =F10+F11 -> 1745589 | G14: =G10+G11 -> 2137901 | H14: =H10+H11 -> 2541290.4 | I14: =I10+I11 -> 2861159.8 | J14: =J10+J11 -> 3191651.6 | ... Q14: =Q10+Q11 -> 5265070.2
B15: Y-O-Y Growth | D15: =D14/C14-1 -> 0.19644657 | E15: =E14/D14-1 -> 0.080927232 | F15: =F14/E14-1 -> 0.15282946 | G15: =G14/F14-1 -> 0.22474477 | H15: =H14/G14-1 -> 0.18868477 | I15: =I14/H14-1 -> 0.12586889 | J15: =J14/I14-1 -> 0.11550975 | K15: =K14/J14-1 -> 0.10516165 | ... Q15: =Q14/P14-1 -> 0.043674675
B17: Share of Profit/(Loss) of Associates | C17: ='P&L Input'!C33 -> -24232 | D17: ='P&L Input'!D33 -> -7521 | E17: ='P&L Input'!E33 -> -27094 | F17: ='P&L Input'!F33 -> -37030 | G17: ='P&L Input'!G33 -> -3645 | H17: =H10*H18 -> -33803.03 | I17: =I10*I18 -> -38057.78 | J17: =J10*J18 -> -42453.824 | K17: =K10*K18 -> -46918.339 | L17: =L10*L18 -> -51367.633 | M17: =M10*M18 -> -55709.382 | N17: =N10*N18 -> -59845.582 | O17: =O10*O18 -> -63676.112 | ... Q17: =Q10*Q18 -> -70033.447
C18: =C17/C10 -> -0.02079163 | D18: =D17/D10 -> -0.0054051607 | E18: =E17/E10 -> -0.018064786 | F18: =F17/F10 -> -0.021406456 | G18: =G17/G10 -> -0.0017277109 | H18: =AVERAGE(C18:G18) -> -0.013479149 | I18: =H18 -> -0.013479149 | J18: =I18 -> -0.013479149 | K18: =J18 -> -0.013479149 | L18: =K18 -> -0.013479149 | M18: =L18 -> -0.013479149 | N18: =M18 -> -0.013479149 | O18: =N18 -> -0.013479149 | P18: =O18 -> -0.013479149 | Q18: =P18 -> -0.013479149
B20: ='P&L Input'!B37 -> Exceptional items | C20: ='P&L Input'!C37 -> -16986 | D20: ='P&L Input'!D37 -> 6698 | E20: ='P&L Input'!E37 -> 75723 | F20: ='P&L Input'!F37 -> -72868 | G20: ='P&L Input'!G37 -> 34175 | H20: =H10*H21 -> 7424.1759 | I20: =I10*I21 -> 18260.408 | J20: =J10*J21 -> 21411.363 | K20: =K10*K21 -> -6752.1412 | L20: =L10*L21 -> 23234.969 | M20: =M10*M21 -> 16848.714 | N20: =N10*N21 -> 19090.813 | O20: =O10*O21 -> 18264.853 | ... Q20: =Q10*Q21 -> 22465.982
C21: =C20/C10 -> -0.01457439 | D21: =D20/D10 -> 0.0048136905 | E21: =E20/E10 -> 0.050487924 | F21: =F20/F10 -> -0.042123835 | G21: =G20/G10 -> 0.016198771 | H21: =AVERAGE(C21:G21) -> 0.002960432 | I21: =AVERAGE(D21:H21) -> 0.0064673964 | J21: =AVERAGE(E21:I21) -> 0.0067981376 | K21: =AVERAGE(F21:J21) -> -0.0019398196 | L21: =AVERAGE(G21:K21) -> 0.0060969834 | M21: =AVERAGE(H21:L21) -> 0.004076626 | N21: =AVERAGE(I21:M21) -> 0.0042998648 | O21: =AVERAGE(J21:N21) -> 0.0038663584 | ... Q21: =AVERAGE(L21:P21) -> 0.004323967
B25: Revenue by Service Line | C25: 2022 | D25: =C25+1 -> 2023 | E25: =D25+1 -> 2024 | F25: =E25+1 -> 2025 | G25: =F25+1 -> 2026 | H25: =G25+1 -> 2027 | I25: =H25+1 -> 2028 | J25: =I25+1 -> 2029 | K25: =J25+1 -> 2030 | ... Q25: =P25+1 -> 2036
B26: Mobile Services India | C26: 629149 | D26: 759246 | E26: 850488 | F26: 1002500 | G26: 1129954 | H26: =G26*(1+H27) -> 1308720.7 | I26: =H26*(1+I27) -> 1500064.9 | J26: =I26*(1+J27) -> 1701384.1 | K26: =J26*(1+K27) -> 1909305.3 | L26: =K26*(1+L27) -> 2119724.2 | M26: =L26*(1+M27) -> 2327896 | N26: =M26*(1+N27) -> 2528577 | O26: =N26*(1+O27) -> 2716215.3 | ... Q26: =P26*(1+Q27) -> 3030039.5
D27: =IFERROR(D26/C26-1,"") -> 0.2067825 | E27: =IFERROR(E26/D26-1,"") -> 0.12017449 | F27: =IFERROR(F26/E26-1,"") -> 0.17873503 | G27: =IFERROR(G26/F26-1,"") -> 0.12713616 | H27: =CHOOSE(Assumptions!$D$18,H28,H29,H30) -> 0.15820704 | I27: =CHOOSE(Assumptions!$D$18,I28,I29,I30) -> 0.14620704 | J27: =CHOOSE(Assumptions!$D$18,J28,J29,J30) -> 0.13420704 | K27: =CHOOSE(Assumptions!$D$18,K28,K29,K30) -> 0.12220704 | L27: =CHOOSE(Assumptions!$D$18,L28,L29,L30) -> 0.11020704 | M27: =CHOOSE(Assumptions!$D$18,M28,M29,M30) -> 0.098207044 | N27: =CHOOSE(Assumptions!$D$18,N28,N29,N30) -> 0.086207044 | O27: =CHOOSE(Assumptions!$D$18,O28,O29,O30) -> 0.074207044 | ... Q27: =CHOOSE(Assumptions!$D$18,Q28,Q29,Q30) -> 0.050207044
H28: =H29+0.05 -> 0.20820704 | I28: =I29+0.05 -> 0.19620704 | J28: =J29+0.05 -> 0.18420704 | K28: =K29+0.05 -> 0.17220704 | L28: =L29+0.05 -> 0.16020704 | M28: =M29+0.05 -> 0.14820704 | N28: =N29+0.05 -> 0.13620704 | O28: =O29+0.05 -> 0.12420704 | ... Q28: =Q29+0.05 -> 0.10020704
H29: =AVERAGE(D27:G27) -> 0.15820704 | I29: =H29-0.012 -> 0.14620704 | J29: =I29-0.012 -> 0.13420704 | K29: =J29-0.012 -> 0.12220704 | L29: =K29-0.012 -> 0.11020704 | M29: =L29-0.012 -> 0.098207044 | N29: =M29-0.012 -> 0.086207044 | O29: =N29-0.012 -> 0.074207044 | P29: =O29-0.012 -> 0.062207044 | Q29: =P29-0.012 -> 0.050207044
H30: =H29-0.05 -> 0.10820704 | I30: =I29-0.05 -> 0.096207044 | J30: =J29-0.05 -> 0.084207044 | K30: =K29-0.05 -> 0.072207044 | L30: =L29-0.05 -> 0.060207044 | M30: =M29-0.05 -> 0.048207044 | N30: =N29-0.05 -> 0.036207044 | O30: =O29-0.05 -> 0.024207044 | ... Q30: =Q29-0.05 -> 0.00020704393
B32: Mobile Services Africa | C32: 350612 | D32: 422664 | E32: 411841 | F32: 418795 | G32: 568064 | H32: =G32*(1+H33) -> 646628.25 | I32: =H32*(1+I33) -> 728298.53 | J32: =I32*(1+J33) -> 811544.34 | K32: =J32*(1+K33) -> 894566.75 | L32: =K32*(1+L33) -> 975347.7 | M32: =L32*(1+M33) -> 1051719.1 | N32: =M32*(1+N33) -> 1121450 | O32: =N32*(1+O33) -> 1182346.7 | ... Q32: =P32*(1+Q33) -> 1269704.7
D33: =IFERROR(D32/C32-1,"") -> 0.20550352 | E33: =IFERROR(E32/D32-1,"") -> -0.025606628 | F33: =IFERROR(F32/E32-1,"") -> 0.016885157 | G33: =IFERROR(G32/F32-1,"") -> 0.35642498 | H33: =CHOOSE(Assumptions!$D$18,H34,H35,H36) -> 0.13830176 | I33: =CHOOSE(Assumptions!$D$18,I34,I35,I36) -> 0.12630176 | J33: =CHOOSE(Assumptions!$D$18,J34,J35,J36) -> 0.11430176 | K33: =CHOOSE(Assumptions!$D$18,K34,K35,K36) -> 0.10230176 | L33: =CHOOSE(Assumptions!$D$18,L34,L35,L36) -> 0.090301757 | M33: =CHOOSE(Assumptions!$D$18,M34,M35,M36) -> 0.078301757 | N33: =CHOOSE(Assumptions!$D$18,N34,N35,N36) -> 0.066301757 | O33: =CHOOSE(Assumptions!$D$18,O34,O35,O36) -> 0.054301757 | ... Q33: =CHOOSE(Assumptions!$D$18,Q34,Q35,Q36) -> 0.030301757
H34: =H35+0.05 -> 0.18830176 | I34: =I35+0.05 -> 0.17630176 | J34: =J35+0.05 -> 0.16430176 | K34: =K35+0.05 -> 0.15230176 | L34: =L35+0.05 -> 0.14030176 | M34: =M35+0.05 -> 0.12830176 | N34: =N35+0.05 -> 0.11630176 | O34: =O35+0.05 -> 0.10430176 | ... Q34: =Q35+0.05 -> 0.080301757
H35: =AVERAGE(D33:G33) -> 0.13830176 | I35: =H35-0.012 -> 0.12630176 | J35: =I35-0.012 -> 0.11430176 | K35: =J35-0.012 -> 0.10230176 | L35: =K35-0.012 -> 0.090301757 | M35: =L35-0.012 -> 0.078301757 | N35: =M35-0.012 -> 0.066301757 | O35: =N35-0.012 -> 0.054301757 | P35: =O35-0.012 -> 0.042301757 | Q35: =P35-0.012 -> 0.030301757
H36: =H35-0.05 -> 0.088301757 | I36: =I35-0.05 -> 0.076301757 | J36: =J35-0.05 -> 0.064301757 | K36: =K35-0.05 -> 0.052301757 | L36: =L35-0.05 -> 0.040301757 | M36: =M35-0.05 -> 0.028301757 | N36: =N35-0.05 -> 0.016301757 | O36: =O35-0.05 -> 0.0043017574 | ... Q36: =Q35-0.05 -> -0.019698243
B38: Mobile Services South Asia | C38: 3869 | D38: 2944 | E38: 3773 | F38: 941 | G38: 0 | H38: 0 | I38: 0 | J38: 0 | K38: 0 | L38: 0 | M38: 0 | N38: 0 | O38: 0 | P38: 0 | Q38: 0
D39: =IFERROR(D38/C38-1,"") -> -0.23907987 | E39: =IFERROR(E38/D38-1,"") -> 0.28158967 | F39: =IFERROR(F38/E38-1,"") -> -0.75059634 | G39: =IFERROR(G38/F38-1,"") -> -1
B44: Airtel Business | C44: 160702 | D44: 185931 | E44: 208209 | F44: 220935 | G44: 211766 | H44: =G44*(1+H45) -> 227459.53 | I44: =H44*(1+I45) -> 241586.55 | J44: =I44*(1+J45) -> 253691.94 | K44: =J44*(1+K45) -> 263359.6 | L44: =K44*(1+L45) -> 270235.36 | M44: =L44*(1+M45) -> 274047.8 | N44: =M44*(1+N45) -> 274625.46 | O44: =N44*(1+O45) -> 271908.83 | ... Q44: =P44*(1+Q45) -> 256942.34
D45: =IFERROR(D44/C44-1,"") -> 0.15699245 | E45: =IFERROR(E44/D44-1,"") -> 0.11981864 | F45: =IFERROR(F44/E44-1,"") -> 0.061121277 | G45: =IFERROR(G44/F44-1,"") -> -0.041500894 | H45: =CHOOSE(Assumptions!$D$18,H46,H47,H48) -> 0.074107868 | I45: =CHOOSE(Assumptions!$D$18,I46,I47,I48) -> 0.062107868 | J45: =CHOOSE(Assumptions!$D$18,J46,J47,J48) -> 0.050107868 | K45: =CHOOSE(Assumptions!$D$18,K46,K47,K48) -> 0.038107868 | L45: =CHOOSE(Assumptions!$D$18,L46,L47,L48) -> 0.026107868 | M45: =CHOOSE(Assumptions!$D$18,M46,M47,M48) -> 0.014107868 | N45: =CHOOSE(Assumptions!$D$18,N46,N47,N48) -> 0.0021078678 | O45: =CHOOSE(Assumptions!$D$18,O46,O47,O48) -> -0.0098921322 | ... Q45: =CHOOSE(Assumptions!$D$18,Q46,Q47,Q48) -> -0.033892132
H46: =H47+0.05 -> 0.12410787 | I46: =I47+0.05 -> 0.11210787 | J46: =J47+0.05 -> 0.10010787 | K46: =K47+0.05 -> 0.088107868 | L46: =L47+0.05 -> 0.076107868 | M46: =M47+0.05 -> 0.064107868 | N46: =N47+0.05 -> 0.052107868 | O46: =O47+0.05 -> 0.040107868 | ... Q46: =Q47+0.05 -> 0.016107868
H47: =AVERAGE(D45:G45) -> 0.074107868 | I47: =H47-0.012 -> 0.062107868 | J47: =I47-0.012 -> 0.050107868 | K47: =J47-0.012 -> 0.038107868 | L47: =K47-0.012 -> 0.026107868 | M47: =L47-0.012 -> 0.014107868 | N47: =M47-0.012 -> 0.0021078678 | O47: =N47-0.012 -> -0.0098921322 | P47: =O47-0.012 -> -0.021892132 | Q47: =P47-0.012 -> -0.033892132
H48: =H47-0.05 -> 0.024107868 | I48: =I47-0.05 -> 0.012107868 | J48: =J47-0.05 -> 0.00010786782 | K48: =K47-0.05 -> -0.011892132 | L48: =L47-0.05 -> -0.023892132 | M48: =M47-0.05 -> -0.035892132 | N48: =N47-0.05 -> -0.047892132 | O48: =O47-0.05 -> -0.059892132 | ... Q48: =Q47-0.05 -> -0.083892132
B50: Passive Infrastructure Services | C50: 0 | D50: 0 | E50: 0 | F50: 112920 | G50: 326944 | H50: =G50*(1+H51) -> 353099.52 | I50: =H50*(1+I51) -> 377110.29 | J50: =I50*(1+J51) -> 398228.46 | K50: =J50*(1+K51) -> 415750.52 | L50: =K50*(1+L51) -> 429054.53 | M50: =L50*(1+M51) -> 437635.62 | N50: =M50*(1+N51) -> 441136.71 | O50: =N50*(1+O51) -> 439372.16 | ... Q50: =P50*(1+Q51) -> 420236.62
D51: =IFERROR(D50/C50-1,"") | E51: =IFERROR(E50/D50-1,"") | F51: =IFERROR(F50/E50-1,"") | G51: =IFERROR(G50/F50-1,"") -> 1.8953595 | H51: =CHOOSE(Assumptions!$D$18,H52,H53,H54) -> 0.08 | I51: =CHOOSE(Assumptions!$D$18,I52,I53,I54) -> 0.068 | J51: =CHOOSE(Assumptions!$D$18,J52,J53,J54) -> 0.056 | K51: =CHOOSE(Assumptions!$D$18,K52,K53,K54) -> 0.044 | L51: =CHOOSE(Assumptions!$D$18,L52,L53,L54) -> 0.032 | M51: =CHOOSE(Assumptions!$D$18,M52,M53,M54) -> 0.02 | N51: =CHOOSE(Assumptions!$D$18,N52,N53,N54) -> 0.008 | O51: =CHOOSE(Assumptions!$D$18,O52,O53,O54) -> -0.004 | ... Q51: =CHOOSE(Assumptions!$D$18,Q52,Q53,Q54) -> -0.028
H52: =H53+0.05 -> 0.13 | I52: =I53+0.05 -> 0.118 | J52: =J53+0.05 -> 0.106 | K52: =K53+0.05 -> 0.094 | L52: =L53+0.05 -> 0.082 | M52: =M53+0.05 -> 0.07 | N52: =N53+0.05 -> 0.058 | O52: =O53+0.05 -> 0.046 | ... Q52: =Q53+0.05 -> 0.022
H53: 0.08 | I53: =H53-0.012 -> 0.068 | J53: =I53-0.012 -> 0.056 | K53: =J53-0.012 -> 0.044 | L53: =K53-0.012 -> 0.032 | M53: =L53-0.012 -> 0.02 | N53: =M53-0.012 -> 0.008 | O53: =N53-0.012 -> -0.004 | P53: =O53-0.012 -> -0.016 | Q53: =P53-0.012 -> -0.028
H54: =H53-0.05 -> 0.03 | I54: =I53-0.05 -> 0.018 | J54: =J53-0.05 -> 0.006 | K54: =K53-0.05 -> -0.006 | L54: =L53-0.05 -> -0.018 | M54: =M53-0.05 -> -0.03 | N54: =N53-0.05 -> -0.042 | O54: =O53-0.05 -> -0.054 | ... Q54: =Q53-0.05 -> -0.078
B56: Homes Services | C56: 30390 | D56: 40472 | E56: 49701 | F56: 59044 | G56: 77747 | H56: =G56*(1+H57) -> 98438.12 | I56: =H56*(1+I57) -> 123454.59 | J56: =I56*(1+J57) -> 153347.15 | K56: =J56*(1+K57) -> 188637.54 | L56: =K56*(1+L57) -> 229785.8 | M56: =L56*(1+M57) -> 277152.46 | N56: =M56*(1+N57) -> 330957.17 | O56: =N56*(1+O57) -> 391235.73 | ... Q56: =P56*(1+Q57) -> 530191.69
D57: =IFERROR(D56/C56-1,"") -> 0.33175387 | E57: =IFERROR(E56/D56-1,"") -> 0.2280342 | F57: =IFERROR(F56/E56-1,"") -> 0.18798415 | G57: =IFERROR(G56/F56-1,"") -> 0.31676377 | H57: =CHOOSE(Assumptions!$D$18,H58,H59,H60) -> 0.26613399 | I57: =CHOOSE(Assumptions!$D$18,I58,I59,I60) -> 0.25413399 | J57: =CHOOSE(Assumptions!$D$18,J58,J59,J60) -> 0.24213399 | K57: =CHOOSE(Assumptions!$D$18,K58,K59,K60) -> 0.23013399 | L57: =CHOOSE(Assumptions!$D$18,L58,L59,L60) -> 0.21813399 | M57: =CHOOSE(Assumptions!$D$18,M58,M59,M60) -> 0.20613399 | N57: =CHOOSE(Assumptions!$D$18,N58,N59,N60) -> 0.19413399 | O57: =CHOOSE(Assumptions!$D$18,O58,O59,O60) -> 0.18213399 | ... Q57: =CHOOSE(Assumptions!$D$18,Q58,Q59,Q60) -> 0.15813399
H58: =H59+0.05 -> 0.31613399 | I58: =I59+0.05 -> 0.30413399 | J58: =J59+0.05 -> 0.29213399 | K58: =K59+0.05 -> 0.28013399 | L58: =L59+0.05 -> 0.26813399 | M58: =M59+0.05 -> 0.25613399 | N58: =N59+0.05 -> 0.24413399 | O58: =O59+0.05 -> 0.23213399 | ... Q58: =Q59+0.05 -> 0.20813399
...

Sheet Cost Builup
A1: Bharti Airtel Ltd
B7: Cost Build-up
B8: Particulars | C8: =FAS!C7 -> 2022 | D8: =FAS!D7 -> 2023 | E8: =FAS!E7 -> 2024 | F8: =FAS!F7 -> 2025 | G8: =FAS!G7 -> 2026 | H8: =FAS!H7 -> 2027 | I8: =FAS!I7 -> 2028 | J8: =FAS!J7 -> 2029 | ... Q8: =FAS!Q7 -> 2036
C9: Audited | D9: Audited | E9: Audited | F9: Audited | G9: Audited | H9: Estimated | I9: Projected | J9: Projected | K9: Projected | L9: Projected | M9: Projected | N9: Projected | O9: Projected | P9: Projected | Q9: Projected
B11: Revenue from Operations | C11: ='Revenue Buildup'!C14 -> 1170812 | D11: ='Revenue Buildup'!D14 -> 1400814 | E11: ='Revenue Buildup'!E14 -> 1514178 | F11: ='Revenue Buildup'!F14 -> 1745589 | G11: ='Revenue Buildup'!G14 -> 2137901 | H11: ='Revenue Buildup'!H14 -> 2541290.4 | I11: ='Revenue Buildup'!I14 -> 2861159.8 | J11: ='Revenue Buildup'!J14 -> 3191651.6 | ... Q11: ='Revenue Buildup'!Q14 -> 5265070.2
B13: ='P&L Input'!B17 -> Network operating expenses | C13: ='P&L Input'!C17 -> 250205 | D13: ='P&L Input'!D17 -> 285433 | E13: ='P&L Input'!E17 -> 300188 | F13: ='P&L Input'!F17 -> 335043 | G13: ='P&L Input'!G17 -> 397500 | H13: =H11*H14 -> 504996.47 | I13: =I11*I14 -> 568559.82 | J13: =J11*J14 -> 634234.02 | K13: =K11*K14 -> 700931.12 | L13: =L11*L14 -> 767400.83 | M13: =M11*M14 -> 832263.9 | N13: =N11*N14 -> 894056.17 | O13: =O11*O14 -> 951281.93 | ... Q13: =Q11*Q14 -> 1046256.6
C14: =C13/C11 -> 0.21370211 | D14: =D13/D11 -> 0.20376224 | E14: =E13/E11 -> 0.19825146 | F14: =F13/F11 -> 0.19193693 | G14: =G13/G11 -> 0.18593003 | H14: =AVERAGE(C14:G14) -> 0.19871656 | I14: =H14 -> 0.19871656 | J14: =I14 -> 0.19871656 | K14: =J14 -> 0.19871656 | L14: =K14 -> 0.19871656 | M14: =L14 -> 0.19871656 | N14: =M14 -> 0.19871656 | O14: =N14 -> 0.19871656 | P14: =O14 -> 0.19871656 | Q14: =P14 -> 0.19871656
B16: ='P&L Input'!B18 -> Access charges | C16: ='P&L Input'!C18 -> 67611 | D16: ='P&L Input'!D18 -> 76207 | E16: ='P&L Input'!E18 -> 75185 | F16: ='P&L Input'!F18 -> 71713 | G16: ='P&L Input'!G18 -> 55416 | H16: =H17*H11 -> 116292.6 | I16: =I17*I11 -> 130930.22 | J16: =J17*J11 -> 146053.94 | K16: =K17*K11 -> 161413.21 | L16: =L17*L11 -> 176720.13 | M16: =M17*M11 -> 191657.05 | N16: =N17*N11 -> 205886.82 | O16: =O17*O11 -> 219065 | ... Q16: =Q17*Q11 -> 240936.15
C17: =C16/C11 -> 0.057747102 | D17: =D16/D11 -> 0.054401941 | E17: =E16/E11 -> 0.049654004 | F17: =F16/F11 -> 0.041082408 | G17: =G16/G11 -> 0.025920751 | H17: =AVERAGE(C17:G17) -> 0.045761241 | I17: =H17 -> 0.045761241 | J17: =I17 -> 0.045761241 | K17: =J17 -> 0.045761241 | L17: =K17 -> 0.045761241 | M17: =L17 -> 0.045761241 | N17: =M17 -> 0.045761241 | O17: =N17 -> 0.045761241 | P17: =O17 -> 0.045761241 | Q17: =P17 -> 0.045761241
B19: ='P&L Input'!B19 -> License fee / Spectrum charges | C19: ='P&L Input'!C19 -> 110636 | D19: ='P&L Input'!D19 -> 117517 | E19: ='P&L Input'!E19 -> 120358 | F19: ='P&L Input'!F19 -> 138290 | G19: ='P&L Input'!G19 -> 153729 | H19: =H11*H20 -> 207879.3 | I19: =I11*I20 -> 234044.84 | J19: =J11*J20 -> 261079.3 | K19: =K11*K20 -> 288534.83 | L19: =L11*L20 -> 315896.76 | M19: =M11*M20 -> 342597.32 | N19: =N11*N20 -> 368033.81 | O19: =O11*O20 -> 391590.51 | ... Q19: =Q11*Q20 -> 430686.37
C20: =C19/C11 -> 0.094495103 | D20: =D19/D11 -> 0.083891937 | E20: =E19/E11 -> 0.079487352 | F20: =F19/F11 -> 0.079222543 | G20: =G19/G11 -> 0.07190651 | H20: =AVERAGE(C20:G20) -> 0.081800689 | I20: =H20 -> 0.081800689 | J20: =I20 -> 0.081800689 | K20: =J20 -> 0.081800689 | L20: =K20 -> 0.081800689 | M20: =L20 -> 0.081800689 | N20: =M20 -> 0.081800689 | O20: =N20 -> 0.081800689 | P20: =O20 -> 0.081800689 | Q20: =P20 -> 0.081800689
B22: ='P&L Input'!B20 -> Employee benefits expense | C22: ='P&L Input'!C20 -> 44333 | D22: ='P&L Input'!D20 -> 48308 | E22: ='P&L Input'!E20 -> 53231 | F22: ='P&L Input'!F20 -> 63089 | G22: ='P&L Input'!G20 -> 75813 | H22: =H11*H23 -> 91033.726 | I22: =I11*I23 -> 102492.04 | J22: =J11*J23 -> 114330.87 | K22: =K11*K23 -> 126354.09 | L22: =L11*L23 -> 138336.33 | M22: =M11*M23 -> 150028.94 | N22: =N11*N23 -> 161167.99 | O22: =O11*O23 -> 171483.85 | ... Q22: =Q11*Q23 -> 188604.56
C23: =C22/C11 -> 0.037865174 | D23: =D22/D11 -> 0.034485663 | E23: =E22/E11 -> 0.035155048 | F23: =F22/F11 -> 0.036141956 | G23: =G22/G11 -> 0.035461418 | H23: =AVERAGE(C23:G23) -> 0.035821852 | I23: =H23 -> 0.035821852 | J23: =I23 -> 0.035821852 | K23: =J23 -> 0.035821852 | L23: =K23 -> 0.035821852 | M23: =L23 -> 0.035821852 | N23: =M23 -> 0.035821852 | O23: =N23 -> 0.035821852 | P23: =O23 -> 0.035821852 | Q23: =P23 -> 0.035821852
B25: ='P&L Input'!B21 -> Sales and marketing expenses | C25: ='P&L Input'!C21 -> 53035 | D25: ='P&L Input'!D21 -> 72454 | E25: ='P&L Input'!E21 -> 107882 | F25: ='P&L Input'!F21 -> 114601 | G25: ='P&L Input'!G21 -> 131073 | H25: =H11*H26 -> 150052.66 | I25: =I11*I26 -> 168939.62 | J25: =J11*J26 -> 188453.8 | K25: =K11*K26 -> 208271.91 | L25: =L11*L26 -> 228022.46 | M25: =M11*M26 -> 247295.61 | N25: =N11*N26 -> 265656.33 | O25: =O11*O26 -> 282660.16 | ... Q25: =Q11*Q26 -> 310880.57
C26: =C25/C11 -> 0.045297623 | D26: =D25/D11 -> 0.051722784 | E26: =E25/E11 -> 0.071247898 | F26: =F25/F11 -> 0.065651766 | G26: =G25/G11 -> 0.0613092 | H26: =AVERAGE(C26:G26) -> 0.059045854 | I26: =H26 -> 0.059045854 | J26: =I26 -> 0.059045854 | K26: =J26 -> 0.059045854 | L26: =K26 -> 0.059045854 | M26: =L26 -> 0.059045854 | N26: =M26 -> 0.059045854 | O26: =N26 -> 0.059045854 | P26: =O26 -> 0.059045854 | Q26: =P26 -> 0.059045854
B28: ='P&L Input'!B22 -> Other expenses | C28: ='P&L Input'!C22 -> 64310 | D28: ='P&L Input'!D22 -> 78794 | E28: ='P&L Input'!E22 -> 60062 | F28: ='P&L Input'!F22 -> 75524 | G28: ='P&L Input'!G22 -> 99452 | H28: =H11*H29 -> 122300.6 | I28: =I11*I29 -> 137694.44 | J28: =J11*J29 -> 153599.49 | K28: =K11*K29 -> 169752.27 | L28: =L11*L29 -> 185849.98 | M28: =M11*M29 -> 201558.59 | N28: =N11*N29 -> 216523.51 | O28: =O11*O29 -> 230382.51 | ... Q28: =Q11*Q29 -> 253383.58
C29: =C28/C11 -> 0.054927691 | D29: =D28/D11 -> 0.056248724 | E29: =E28/E11 -> 0.039666406 | F29: =F28/F11 -> 0.043265626 | G29: =G28/G11 -> 0.046518524 | H29: =AVERAGE(C29:G29) -> 0.048125394 | I29: =H29 -> 0.048125394 | J29: =I29 -> 0.048125394 | K29: =J29 -> 0.048125394 | L29: =K29 -> 0.048125394 | M29: =L29 -> 0.048125394 | N29: =M29 -> 0.048125394 | O29: =N29 -> 0.048125394 | P29: =O29 -> 0.048125394 | Q29: =P29 -> 0.048125394
B31: ='P&L Input'!B32 -> Finance Costs | C31: ='P&L Input'!C32 -> 166162 | D31: ='P&L Input'!D32 -> 192999 | E31: ='P&L Input'!E32 -> 226477 | F31: ='P&L Input'!F32 -> 217539 | G31: ='P&L Input'!G32 -> 215553 | H31: =H32*H11 -> 332763.81 | I31: =I32*I11 -> 374648.42 | J31: =J32*J11 -> 417923.97 | K31: =K32*K11 -> 461873.55 | L31: =L32*L11 -> 505673.29 | M31: =M32*M11 -> 548414.34 | N31: =N32*N11 -> 589131.92 | O31: =O32*O11 -> 626840.42 | ... Q31: =Q32*Q11 -> 689423.31
C32: =C31/C11 -> 0.14192031 | D32: =D31/D11 -> 0.13777632 | E32: =E31/E11 -> 0.14957092 | F32: =F31/F11 -> 0.12462212 | G32: =G31/G11 -> 0.10082459 | H32: =AVERAGE(C32:G32) -> 0.13094285 | I32: =H32 -> 0.13094285 | J32: =I32 -> 0.13094285 | K32: =J32 -> 0.13094285 | L32: =K32 -> 0.13094285 | M32: =L32 -> 0.13094285 | N32: =M32 -> 0.13094285 | O32: =N32 -> 0.13094285 | P32: =O32 -> 0.13094285 | Q32: =P32 -> 0.13094285
B34: Effective Tax rate | C34: ='P&L Input'!C41/'P&L Input'!C39 -> 0.33468449 | D34: ='P&L Input'!D41/'P&L Input'!D39 -> 0.25803861 | E34: ='P&L Input'!E41/'P&L Input'!E39 -> 0.32502563 | F34: ='P&L Input'!F41/'P&L Input'!F39 -> 0.02388635 | G34: ='P&L Input'!G41/'P&L Input'!G39 -> 0.25125574 | H34: =G34+0.5% -> 0.25625574 | I34: =H34 -> 0.25625574 | J34: =I34+0.5% -> 0.26125574 | K34: =J34 -> 0.26125574 | L34: =K34+0.5% -> 0.26625574 | M34: =L34 -> 0.26625574 | N34: =M34+0.5% -> 0.27125574 | O34: =N34 -> 0.27125574 | P34: =O34+0.5% -> 0.27625574 | Q34: =P34 -> 0.27625574

Sheet FAS
A1: Bharti Airtel Ltd
Q5: (INR in millions)
B6: Fixed Assets Schedule
B7: Particulars | C7: 2022 | D7: =C7+1 -> 2023 | E7: =D7+1 -> 2024 | F7: =E7+1 -> 2025 | G7: =F7+1 -> 2026 | H7: =G7+1 -> 2027 | I7: =H7+1 -> 2028 | J7: =I7+1 -> 2029 | K7: =J7+1 -> 2030 | ... Q7: =P7+1 -> 2036
C8: Audited | D8: Audited | E8: Audited | F8: Audited | G8: Audited | H8: Estimated | I8: Projected | J8: Projected | K8: Projected | L8: Projected | M8: Projected | N8: Projected | O8: Projected | P8: Projected | Q8: Projected
B9: PPE Assets
B10: Leasehold Improvements
B11: Opening Gross Block | C11: 10357 | D11: =C15 -> 10512 | E11: =D15 -> 10880 | F11: =E15 -> 10729 | G11: =F15 -> 11075 | H11: =G15 -> 11075 | I11: =H15 -> 11559.4 | J11: =I15 -> 12043.8 | K11: =J15 -> 12528.2 | ... Q11: =P15 -> 17410.952
B12: Additions | C12: 202 | D12: 335 | E12: 264 | F12: =167+11 -> 178 | H12: =F12*1.4 -> 249.2 | I12: =H12 -> 249.2 | J12: =I12 -> 249.2 | K12: =J12*1.4 -> 348.88 | L12: =K12 -> 348.88 | M12: =L12 -> 348.88 | N12: =M12*1.4 -> 488.432 | O12: =N12 -> 488.432 | P12: =O12 -> 488.432 | Q12: =P12*1.4 -> 683.8048
B13: Disposals / Adjustments | C13: -49 | D13: 8 | E13: -9 | F13: =84-23-11 -> 50 | H13: =F13*1.4 -> 70 | I13: =H13 -> 70 | J13: =I13 -> 70 | K13: =J13*1.4 -> 98 | L13: =K13 -> 98 | M13: =L13 -> 98 | N13: =M13*1.4 -> 137.2 | O13: =N13 -> 137.2 | P13: =O13 -> 137.2 | Q13: =P13*1.4 -> 192.08
B14: Exchange Differences | C14: 2 | D14: 25 | E14: -406 | F14: 118 | H14: =F14*1.4 -> 165.2 | I14: =H14 -> 165.2 | J14: =I14 -> 165.2 | K14: =J14*1.4 -> 231.28 | L14: =K14 -> 231.28 | M14: =L14 -> 231.28 | N14: =M14*1.4 -> 323.792 | O14: =N14 -> 323.792 | P14: =O14 -> 323.792 | Q14: =P14*1.4 -> 453.3088
B15: Closing Gross Block | C15: =SUM(C11:C14) -> 10512 | D15: =SUM(D11:D14) -> 10880 | E15: =SUM(E11:E14) -> 10729 | F15: =SUM(F11:F14) -> 11075 | G15: =SUM(G11:G14) -> 11075 | H15: =SUM(H11:H14) -> 11559.4 | I15: =SUM(I11:I14) -> 12043.8 | J15: =SUM(J11:J14) -> 12528.2 | ... Q15: =SUM(Q11:Q14) -> 18740.146
B17: Opening Accumulated Depreciation | C17: 8464 | D17: =C21 -> 8761 | E17: =D21 -> 9139 | F17: =E21 -> 9097 | G17: =F21 -> 9273 | H17: =G21 -> 9273 | I17: =H21 -> 10076.6 | J17: =I21 -> 10880.2 | K17: =J21 -> 11683.8 | ... Q17: =P21 -> 19784.088
B18: Depreciation | C18: 361 | D18: 345 | E18: 398 | H18: =E18*1.4 -> 557.2 | I18: =H18 -> 557.2 | J18: =I18 -> 557.2 | K18: =J18*1.4 -> 780.08 | L18: =K18 -> 780.08 | M18: =L18 -> 780.08 | N18: =M18*1.4 -> 1092.112 | O18: =N18 -> 1092.112 | P18: =O18 -> 1092.112 | Q18: =P18*1.4 -> 1528.9568
B19: Disposals / Adjustments | C19: -45 | D19: -2 | E19: -29 | F19: =83-27-10 -> 46 | H19: =F19*1.4 -> 64.4 | I19: =H19 -> 64.4 | J19: =I19 -> 64.4 | K19: =J19*1.4 -> 90.16 | L19: =K19 -> 90.16 | M19: =L19 -> 90.16 | N19: =M19*1.4 -> 126.224 | O19: =N19 -> 126.224 | P19: =O19 -> 126.224 | Q19: =P19*1.4 -> 176.7136
B20: Exchange Differences | C20: -19 | D20: 35 | E20: -411 | F20: 130 | H20: =F20*1.4 -> 182 | I20: =H20 -> 182 | J20: =I20 -> 182 | K20: =J20*1.4 -> 254.8 | L20: =K20 -> 254.8 | M20: =L20 -> 254.8 | N20: =M20*1.4 -> 356.72 | O20: =N20 -> 356.72 | P20: =O20 -> 356.72 | Q20: =P20*1.4 -> 499.408
B21: Closing Accumulated Depreciation | C21: =SUM(C17:C20) -> 8761 | D21: =SUM(D17:D20) -> 9139 | E21: =SUM(E17:E20) -> 9097 | F21: =SUM(F17:F20) -> 9273 | G21: =SUM(G17:G20) -> 9273 | H21: =SUM(H17:H20) -> 10076.6 | I21: =SUM(I17:I20) -> 10880.2 | J21: =SUM(J17:J20) -> 11683.8 | ... Q21: =SUM(Q17:Q20) -> 21989.166
B23: Net Block | C23: =+C15-C21 -> 1751 | D23: =+D15-D21 -> 1741 | E23: =+E15-E21 -> 1632 | F23: =+F15-F21 -> 1802 | G23: =+G15-G21 -> 1802 | H23: =+H15-H21 -> 1482.8 | I23: =+I15-I21 -> 1163.6 | J23: =+J15-J21 -> 844.4 | ... Q23: =+Q15-Q21 -> -3249.0208
B25: Buildings
B26: Opening Gross Block | C26: 10731 | D26: =+C30 -> 13767 | E26: =+D30 -> 18152 | F26: =+E30 -> 17608 | G26: =+F30 -> 24796 | H26: =+G30 -> 24796 | I26: =+H30 -> 34859.2 | J26: =+I30 -> 44922.4 | K26: =+J30 -> 54985.6 | ... Q26: =+P30 -> 156422.66
B27: Additions | C27: 2897 | D27: 4455 | E27: 370 | F27: 5625 | H27: =F27*1.4 -> 7875 | I27: =H27 -> 7875 | J27: =I27 -> 7875 | K27: =J27*1.4 -> 11025 | L27: =K27 -> 11025 | M27: =L27 -> 11025 | N27: =M27*1.4 -> 15435 | O27: =N27 -> 15435 | P27: =O27 -> 15435 | Q27: =P27*1.4 -> 21609
B28: Disposals / Adjustments | C28: -11 | E28: -252 | F28: =1074-28 -> 1046 | H28: =F28*1.4 -> 1464.4 | I28: =H28 -> 1464.4 | J28: =I28 -> 1464.4 | K28: =J28*1.4 -> 2050.16 | L28: =K28 -> 2050.16 | M28: =L28 -> 2050.16 | N28: =M28*1.4 -> 2870.224 | O28: =N28 -> 2870.224 | P28: =O28 -> 2870.224 | Q28: =P28*1.4 -> 4018.3136
B29: Exchange Differences | C29: 150 | D29: -70 | E29: -662 | F29: 517 | H29: =F29*1.4 -> 723.8 | I29: =H29 -> 723.8 | J29: =I29 -> 723.8 | K29: =J29*1.4 -> 1013.32 | L29: =K29 -> 1013.32 | M29: =L29 -> 1013.32 | N29: =M29*1.4 -> 1418.648 | O29: =N29 -> 1418.648 | P29: =O29 -> 1418.648 | Q29: =P29*1.4 -> 1986.1072
B30: Closing Gross Block | C30: =SUM(C26:C29) -> 13767 | D30: =SUM(D26:D29) -> 18152 | E30: =SUM(E26:E29) -> 17608 | F30: =SUM(F26:F29) -> 24796 | G30: =SUM(G26:G29) -> 24796 | H30: =SUM(H26:H29) -> 34859.2 | I30: =SUM(I26:I29) -> 44922.4 | J30: =SUM(J26:J29) -> 54985.6 | ... Q30: =SUM(Q26:Q29) -> 184036.08
B32: Opening Accumulated Depreciation | C32: 4799 | D32: =+C36 -> 5413 | E32: =+D36 -> 6177 | F32: =+E36 -> 6437 | G32: =+F36 -> 8484 | H32: =+G36 -> 8484 | I32: =+H36 -> 11349.8 | J32: =+I36 -> 14215.6 | K32: =+J36 -> 17081.4 | ... Q32: =+P36 -> 45968.664
B33: Depreciation | C33: 568 | D33: 866 | E33: 859 | F33: 1069 | H33: =F33*1.4 -> 1496.6 | I33: =H33 -> 1496.6 | J33: =I33 -> 1496.6 | K33: =J33*1.4 -> 2095.24 | L33: =K33 -> 2095.24 | M33: =L33 -> 2095.24 | N33: =M33*1.4 -> 2933.336 | O33: =N33 -> 2933.336 | P33: =O33 -> 2933.336 | Q33: =P33*1.4 -> 4106.6704
B34: Disposals / Adjustments | C34: -2 | D34: -5 | E34: -165 | F34: =655-17+4 -> 642 | H34: =F34*1.4 -> 898.8 | I34: =H34 -> 898.8 | J34: =I34 -> 898.8 | K34: =J34*1.4 -> 1258.32 | L34: =K34 -> 1258.32 | M34: =L34 -> 1258.32 | N34: =M34*1.4 -> 1761.648 | O34: =N34 -> 1761.648 | P34: =O34 -> 1761.648 | Q34: =P34*1.4 -> 2466.3072
B35: Exchange Differences | C35: 48 | D35: -97 | E35: -434 | F35: 336 | H35: =F35*1.4 -> 470.4 | I35: =H35 -> 470.4 | J35: =I35 -> 470.4 | K35: =J35*1.4 -> 658.56 | L35: =K35 -> 658.56 | M35: =L35 -> 658.56 | N35: =M35*1.4 -> 921.984 | O35: =N35 -> 921.984 | P35: =O35 -> 921.984 | Q35: =P35*1.4 -> 1290.7776
B36: Closing Accumulated Depreciation | C36: =SUM(C32:C35) -> 5413 | D36: =SUM(D32:D35) -> 6177 | E36: =SUM(E32:E35) -> 6437 | F36: =SUM(F32:F35) -> 8484 | G36: =SUM(G32:G35) -> 8484 | H36: =SUM(H32:H35) -> 11349.8 | I36: =SUM(I32:I35) -> 14215.6 | J36: =SUM(J32:J35) -> 17081.4 | ... Q36: =SUM(Q32:Q35) -> 53832.419
B38: Net Block | C38: =+C30-C36 -> 8354 | D38: =+D30-D36 -> 11975 | E38: =+E30-E36 -> 11171 | F38: =+F30-F36 -> 16312 | G38: =+G30-G36 -> 16312 | H38: =+H30-H36 -> 23509.4 | I38: =+I30-I36 -> 30706.8 | J38: =+J30-J36 -> 37904.2 | ... Q38: =+Q30-Q36 -> 130203.66
B40: Land
B41: Opening Gross Block | C41: 5843 | D41: =+C45 -> 5798 | E41: =+D45 -> 8238 | F41: =+E45 -> 9415 | G41: =+F45 -> 10112 | H41: =+G45 -> 10112 | I41: =+H45 -> 11087.8 | J41: =+I45 -> 12063.6 | K41: =+J45 -> 13039.4 | ... Q41: =+P45 -> 22875.464
B42: Additions | C42: 145 | D42: 2355 | E42: 1350 | F42: =652+4 -> 656 | H42: =F42*1.4 -> 918.4 | I42: =H42 -> 918.4 | J42: =I42 -> 918.4 | K42: =J42*1.4 -> 1285.76 | L42: =K42 -> 1285.76 | M42: =L42 -> 1285.76 | N42: =M42*1.4 -> 1800.064 | O42: =N42 -> 1800.064 | P42: =O42 -> 1800.064 | Q42: =P42*1.4 -> 2520.0896
B43: Disposals / Adjustments | C43: -185 | D43: 0 | E43: -44 | F43: =25-6 -> 19 | H43: =F43*1.4 -> 26.6 | I43: =H43 -> 26.6 | J43: =I43 -> 26.6 | K43: =J43*1.4 -> 37.24 | L43: =K43 -> 37.24 | M43: =L43 -> 37.24 | N43: =M43*1.4 -> 52.136 | O43: =N43 -> 52.136 | P43: =O43 -> 52.136 | Q43: =P43*1.4 -> 72.9904
B44: Exchange Differences | C44: -5 | D44: 85 | E44: -129 | F44: 22 | H44: =F44*1.4 -> 30.8 | I44: =H44 -> 30.8 | J44: =I44 -> 30.8 | K44: =J44*1.4 -> 43.12 | L44: =K44 -> 43.12 | M44: =L44 -> 43.12 | N44: =M44*1.4 -> 60.368 | O44: =N44 -> 60.368 | P44: =O44 -> 60.368 | Q44: =P44*1.4 -> 84.5152
B45: Closing Gross Block | C45: =SUM(C41:C44) -> 5798 | D45: =SUM(D41:D44) -> 8238 | E45: =SUM(E41:E44) -> 9415 | F45: =SUM(F41:F44) -> 10112 | G45: =SUM(G41:G44) -> 10112 | H45: =SUM(H41:H44) -> 11087.8 | I45: =SUM(I41:I44) -> 12063.6 | J45: =SUM(J41:J44) -> 13039.4 | ... Q45: =SUM(Q41:Q44) -> 25553.059
B47: Net Block | C47: =+C45 -> 5798 | D47: =+D45 -> 8238 | E47: =+E45 -> 9415 | F47: =+F45 -> 10112 | G47: =+G45 -> 10112 | H47: =+H45 -> 11087.8 | I47: =+I45 -> 12063.6 | J47: =+J45 -> 13039.4 | ... Q47: =+Q45 -> 25553.059
B49: Plant & Equipment
B50: Opening Gross Block | C50: 1926716 | D50: =+C54 -> 2105395 | E50: =+D54 -> 2284891 | F50: =+E54 -> 2431350 | G50: =+F54 -> 2950094 | H50: =+G54 -> 3087684 | I50: =+H54 -> 3813925.6 | J50: =+I54 -> 4540167.2 | K50: =+J54 -> 5266408.8 | ... Q50: =+P54 -> 12586924
B51: Additions | C51: 231788 | D51: 231784 | E51: =381615+1 -> 381616 | F51: =336681+271296 -> 607977 | G51: 137590 | H51: =F51*1.4 -> 851167.8 | I51: =H51 -> 851167.8 | J51: =I51 -> 851167.8 | K51: =J51*1.4 -> 1191634.9 | L51: =K51 -> 1191634.9 | M51: =L51 -> 1191634.9 | N51: =M51*1.4 -> 1668288.9 | O51: =N51 -> 1668288.9 | P51: =O51 -> 1668288.9 | Q51: =P51*1.4 -> 2335604.4
...

Sheet BS items
A1: Bharti Airtel Ltd
R6: (INR in millions)
B7: Balance Sheet Items
B8: Particulars | D8: =FAS!C7 -> 2022 | E8: =FAS!D7 -> 2023 | F8: =FAS!E7 -> 2024 | G8: =FAS!F7 -> 2025 | H8: =FAS!G7 -> 2026 | I8: =FAS!H7 -> 2027 | J8: =FAS!I7 -> 2028 | K8: =FAS!J7 -> 2029 | ... R8: =FAS!Q7 -> 2036
D9: Audited | E9: Audited | F9: Audited | G9: Audited | H9: Audited | I9: Estimated | J9: Projected | K9: Projected | L9: Projected | M9: Projected | N9: Projected | O9: Projected | P9: Projected | Q9: Projected | R9: Projected
B10: ASSETS
B12: Non-Current Assets
C13: ='BS Input'!B16 -> Investment in Joint Ventures & Associates | D13: ='BS Input'!C16 -> 284268 | E13: ='BS Input'!D16 -> 281838 | F13: ='BS Input'!E16 -> 312404 | G13: ='BS Input'!F16 -> 36416 | H13: ='BS Input'!G16 -> 40622 | I13: ='Revenue Buildup'!H$14*I14 -> 353269.21 | J13: ='Revenue Buildup'!I$14*J14 -> 397734.81 | K13: ='Revenue Buildup'!J$14*K14 -> 443677.06 | L13: ='Revenue Buildup'!K$14*L14 -> 490334.88 | M13: ='Revenue Buildup'!L$14*M14 -> 536833.62 | N13: ='Revenue Buildup'!M$14*N14 -> 582208.44 | O13: ='Revenue Buildup'!N$14*O14 -> 625435.1 | P13: ='Revenue Buildup'!O$14*P14 -> 665467.26 | ... R13: ='Revenue Buildup'!Q$14*R14 -> 731906.59
